name: CI

on:
  push:
    branches:
      - main
  pull_request:

jobs:
  lint:
    runs-on: ubuntu-latest
    steps:
      - uses: actions/checkout@v4
      - uses: ./.github/actions/setup-uv
      - uses: pre-commit/action@v3.0.1

  tests:
    strategy:
      fail-fast: false
      matrix:
        os: [ubuntu-latest]
        python-version: ["3.13"]
    runs-on: ${{ matrix.os }}
    steps:
      - uses: actions/checkout@v4
      - uses: ./.github/actions/setup-uv
        with:
          python-version: ${{ matrix.python-version }}
      - uses: ./.github/actions/install-amici-deps
      - uses: ./.github/actions/install-project-deps
      - uses: ./.github/actions/prepare-cpp-test
      - name: Run pytest
        run: uv run pytest -v
      # TODO: coverage run creates segmentation fault on Github ci, but not locally. Debug it
      # - name: Run coverage
      #   run: |
      #     source $VENV
      #     coverage run -m pytest -v
      #     coverage report
